<?xml version='1.0'?>

<robot name="my_robot" xmlns:xacro="http://www.ros.org/wiki/xacro">
  <gazebo reference="left_wheel">
      <material>Gazebo/Black</material>
  </gazebo>
  <gazebo reference="right_wheel">
      <material>Gazebo/Black</material>
  </gazebo>
  <gazebo reference="chassis">
      <material>Gazebo/Grey</material>
  </gazebo>
  <gazebo reference="camera">
      <material>Gazebo/Green</material>
  </gazebo>
  
  <xacro:include filename="$(find my_robot)/urdf/my_robot.gazebo" />
  <link name="robot_footprint"></link>

  <joint name="robot_footprint_joint" type="fixed">
    <origin xyz="0 0 0" rpy="0 0 0" />
    <parent link="robot_footprint"/>
    <child link="chassis" />
  </joint>

  <joint type="continuous" name="left_wheel_hinge">
    <origin xyz="0 0.15 0" rpy="0 0 0"/>
    <child link="left_wheel"/>
    <parent link="chassis"/>
    <axis xyz="0 1 0" rpy="0 0 0"/>
    <limit effort="10000" velocity="1000"/>
    <dynamics damping="1.0" friction="1.0"/>
  </joint>

  <joint type="continuous" name="right_wheel_hinge">
    <origin xyz="0 -0.15 0" rpy="0 0 0"/>
    <child link="right_wheel"/>
    <parent link="chassis"/>
    <axis xyz="0 1 0" rpy="0 0 0"/>
    <limit effort="10000" velocity="1000"/>
    <dynamics damping="1.0" friction="1.0"/>
  </joint>

  <joint type="fixed" name="camera_joint">
    <axis xyz="0 1 0" />
    <origin xyz="0.2 0 0" rpy="0 0 0" />
    <parent link="chassis" />
    <child link="camera" />
  </joint>

  <joint type='fixed' name='hokuyo_joint'>
    <axis xyz='0 1 0' />
    <origin xyz='0.15 0 0.1' rpy='0 0 0' />
    <parent link="chassis" />
    <child link="hokuyo" />
  </joint>

  <link name='hokuyo'>
    <inertial>
      <mass value="1e-05"/>
      <origin xyz="0.0 0 0" rpy=" 0 0 0"/>
      <inertia
          ixx="1e-06" ixy="0" ixz="0"
          iyy="1e-06" iyz="0"
          izz="1e-06"
      />
    </inertial>
    <visual name='hokyo_visual'>
      <origin xyz="0 0 0" rpy=" 0 0 0"/> 
      <geometry>
        <mesh filename='package://my_robot/meshes/hokuyo.dae'/>
      </geometry>
    </visual>
    <collision name='hokyo_collision'>
      <origin xyz="0 0 0" rpy=" 0 0 0"/> 
      <geometry>
        <box size="0.1 0.1 0.1"/>
      </geometry>
    </collision>
  </link>

  <link name='camera'>
    <inertia>
      <mass value="0.1"/>
      <origin xyz="0.0 0 0" rpy=" 0 0 0"/>
      <inertia
          ixx="1e-06" ixy="0" ixz="0"
          iyy="1e-06" iyz="0"
          izz="1e-06"
      />
    </inertia>
    <visual name='camera_visual'>
      <origin xyz="0 0 0" rpy=" 0 0 0"/> 
      <geometry>
        <box size="0.05 0.05 0.05"/>
      </geometry>
    </visual>
    <collision name='camera_collision'>
      <origin xyz="0 0 0" rpy=" 0 0 0"/> 
      <geometry>
        <box size="0.05 0.05 0.05"/>
      </geometry>
    </collision>
  </link>

  <link name='left_wheel'>
    <pose>0 0 0.1 0 0 0</pose>

    <inertial>
      <mass value="5.0"/>
      <origin xyz="0.0 0 0" rpy=" 0 1.5707 1.5707"/>
      <inertia
          ixx="0.1" ixy="0" ixz="0"
          iyy="0.1" iyz="0"
          izz="0.1"
      />
    </inertial>

    <collision name='left_wheel_collision'>
      <origin xyz="0.0 0 0" rpy=" 0 1.5707 1.5707"/>
      <geometry>
        <cylinder radius="0.13" length="0.03"/>
      </geometry>
    </collision>

    <visual name='left_wheel_visual'>
      <origin xyz="0.0 0 0" rpy=" 0 1.5707 1.5707"/>
      <geometry>
        <cylinder radius="0.13" length="0.03"/>
      </geometry>
    </visual>

  </link>

  <link name='right_wheel'>
    <pose>0 0 0.1 0 0 0</pose>

    <inertial>
      <mass value="5.0"/>
      <origin xyz="0.0 0 0" rpy=" 0 1.5707 1.5707"/>
      <inertia
          ixx="0.1" ixy="0" ixz="0"
          iyy="0.1" iyz="0"
          izz="0.1"
      />
    </inertial>

    <collision name='right_wheel_collision'>
      <origin xyz="0.0 0 0" rpy=" 0 1.5707 1.5707"/>
      <geometry>
        <cylinder radius="0.13" length="0.03"/>
      </geometry>
    </collision>

    <visual name='right_wheel_visual'>
      <origin xyz="0.0 0 0" rpy=" 0 1.5707 1.5707"/>
      <geometry>
        <cylinder radius="0.13" length="0.03"/>
      </geometry>
    </visual>

  </link>
  <link name='chassis'>
    <pose>0 0 0.1 0 0 0</pose>

    <inertial>
      <mass value="15.0"/>
      <origin xyz="0.0 0 0" rpy=" 0 0 0"/>
      <inertia
          ixx="0.1" ixy="0" ixz="0"
          iyy="0.1" iyz="0"
          izz="0.1"
      />
    </inertial>

    <collision name='collision'>
      <origin xyz="0 0 0" rpy=" 0 0 0"/> 
      <geometry>
        <box size=".4 .24 .1"/>
      </geometry>
    </collision>

    <visual name='chassis_visual'>
      <origin xyz="0 0 0" rpy=" 0 0 0"/>
      <geometry>
        <box size=".4 .24 .1"/>
      </geometry>
    </visual>


    <collision name='back_caster_collision'>
      <origin xyz="-0.15 0 -0.075" rpy=" 0 0 0"/>
      <geometry>
        <sphere radius="0.0529"/>
      </geometry>
    </collision>

    <visual name='back_caster_visual'>
      <origin xyz="-0.15 0 -0.075" rpy=" 0 0 0"/>
      <geometry>
        <sphere radius="0.053"/>
      </geometry>
    </visual>

    <collision name='front_caster_collision'>
      <origin xyz="0.15 0 -0.075" rpy=" 0 0 0"/>
      <geometry>
        <sphere radius="0.0529"/>
      </geometry>
    </collision>

    <visual name='front_caster_visual'>
      <origin xyz="0.15 0 -0.075" rpy=" 0 0 0"/>
      <geometry>
        <sphere radius="0.053"/>
      </geometry>
    </visual>

  </link>

</robot>
